Workbook

Sheet Metadata
A1: cod | B1: Variable | C1: Fuente | D1: Sector económico | E1: Unidad | F1: Agregación trimestre | G1: Comentarios
A2: v_1 | B2: IPC Ecuador | F2: Promedio
A3: v_2 | B3: IPC USA | F3: Promedio
A4: v_3 | B4: Gastos (SPNF) | F4: Suma
A5: v_4 | B5: Ingresos (SPNF) | F5: Suma
A6: v_5 | B6: Resultado global (SPNF) | F6: Suma
A7: v_6 | B7: Exportaciones totales | F7: Suma
A8: v_7 | B8: Importaciones totales | F8: Suma
A9: v_8 | B9: Balanza comercial | F9: Suma
A10: v_9 | B10: Precio petróleo WTI | F10: Promedio
A11: v_10 | B11: Pib nominal (Millones USD)
A12: v_11 | B12: Paridad precios EC-USA
A13: v_12 | B13: Deflactor USA, sa, 100=2018
A14: v_13 | B14: Deflactor PIB EC, sa
A15: v_14 | B15: Deflactor PIB EC, sa, base 2014
A16: v_15 | B16: IPC Ecuador, sa, 100=2014, PPP
A17: v_16 | B17: IPC USA, sa, 100=2014
A18: v_17 | B18: Deflactor PIB EC, sa, 100=dic2018, PPP
A19: v_18 | B19: IPC Ecuador, sa, 100=2019, PPP
A20: v_19 | B20: IPC USA, sa, 100=2019
A21: v_20 | B21: Ingresos petroleros SPNF
A22: v_21 | B22: Deflactor PIB GCFH, sa, 100=dic2018, PPP
... A42: V_41 | B42: PIB REAL ECU (1998=100)

Sheet Data
B1: v_1 | C1: v_2 | D1: v_3 | E1: v_4 | F1: v_5 | G1: v_6 | H1: v_7 | I1: v_8 | J1: v_9 | K1: v_11 | L1: V_38 | M1: V_39 | O1: Total ingresos | P1: Ingresos Petroleros | Q1: Ingresos no petroleros | R1: Ingresos tributarios
A2: 36404
A3: 36434 | B3: 21.558464 | C3: 168.2 | L3: =B3*54.2221/B$137 -> 13.577413 | M3: =C3*100/C$137 -> 76.740929 | N3: =L3/M3 -> 0.17692532
A4: 36465 | B4: 22.934536 | C4: 168.3 | L4: =B4*54.2221/B$137 -> 14.444057 | M4: =C4*100/C$137 -> 76.786553 | N4: =L4/M4 -> 0.18810659
A5: 36495 | B5: 24.213474 | C5: 168.3 | L5: =B5*54.2221/B$137 -> 15.249525 | M5: =C5*100/C$137 -> 76.786553 | N5: =L5/M5 -> 0.1985963
A6: 36526 | B6: 27.684413 | C6: 168.8 | L6: =B6*54.2221/B$137 -> 17.435506 | M6: =C6*100/C$137 -> 77.014678 | N6: =L6/M6 -> 0.22639198
A7: 36557 | B7: 30.46246 | C7: 169.8 | L7: =B7*54.2221/B$137 -> 19.185106 | M7: =C7*100/C$137 -> 77.470926 | N7: =L7/M7 -> 0.24764266
A8: 36586 | B8: 32.766707 | C8: 171.2 | L8: =B8*54.2221/B$137 -> 20.636309 | M8: =C8*100/C$137 -> 78.109673 | N8: =L8/M8 -> 0.26419658
A9: 36617 | B9: 36.112451 | C9: 171.3 | L9: =B9*54.2221/B$137 -> 22.743442 | M9: =C9*100/C$137 -> 78.155298 | N9: =L9/M9 -> 0.2910032
A10: 36647 | B10: 37.968799 | C10: 171.5 | L10: =B10*54.2221/B$137 -> 23.91256 | M10: =C10*100/C$137 -> 78.246547 | N10: =L10/M10 -> 0.30560531
A11: 36678 | B11: 39.987038 | C11: 172.4 | L11: =B11*54.2221/B$137 -> 25.183637 | M11: =C11*100/C$137 -> 78.657171 | N11: =L11/M11 -> 0.32016963
A12: 36708 | B12: 40.935719 | C12: 172.8 | L12: =B12*54.2221/B$137 -> 25.781112 | M12: =C12*100/C$137 -> 78.83967 | N12: =L12/M12 -> 0.32700684
A13: 36739 | B13: 41.492623 | C13: 172.8 | L13: =B13*54.2221/B$137 -> 26.131847 | M13: =C13*100/C$137 -> 78.83967 | N13: =L13/M13 -> 0.33145556
A14: 36770 | B14: 43.019793 | C14: 173.7 | L14: =B14*54.2221/B$137 -> 27.093652 | M14: =C14*100/C$137 -> 79.250293 | N14: =L14/M14 -> 0.34187446
... A29: 37226 | B29: 56.624021 | C29: 176.7 | L29: =B29*54.2221/B$137 -> 35.661526 | M29: =C29*100/C$137 -> 80.619037 | N29: =L29/M29 -> 0.44234621
A30: 37257 | B30: 57.646091 | C30: 177.1 | D30: 390.83 | E30: 502.41 | F30: 111.58 | G30: 350.159 | H30: 502 | I30: =G30-H30 -> -151.841 | J30: 19.687619 | K30: 50 | L30: =B30*54.2221/B$137 -> 36.305221 | M30: =C30*100/C$137 -> 80.801537 | N30: =L30/M30 -> 0.4493135 | O30: 502.4135 | P30: 107.782 | Q30: 373.44646 | R30: 248.86259
A31: 37288 | B31: 58.261277 | C31: 177.8 | D31: 462.87 | E31: 490.39 | F31: 27.52 | G31: 346.297 | H31: 406.7 | I31: =G31-H31 -> -60.403 | J31: 20.723158 | K31: 50.533588 | L31: =B31*54.2221/B$137 -> 36.692662 | M31: =C31*100/C$137 -> 81.12091 | N31: =L31/M31 -> 0.45232064 | O31: 490.38181 | P31: 96.136 | Q31: 371.49855 | R31: 203.27867
A32: 37316 | B32: 58.915316 | C32: 178.8 | D32: 411.84 | E32: 443.49 | F32: 31.65 | G32: 405.99 | H32: 448.3 | I32: =G32-H32 -> -42.31 | J32: 24.377 | K32: 51.100876 | L32: =B32*54.2221/B$137 -> 37.104572 | M32: =C32*100/C$137 -> 81.577158 | N32: =L32/M32 -> 0.45484021 | O32: 443.48845 | P32: 84.473 | Q32: 349.1685 | R32: 223.51667
A33: 37347 | B33: 59.796541 | C33: 179.8 | D33: 517.14 | E33: 640.62 | F33: 123.48 | G33: 447.954 | H33: 586.9 | I33: =G33-H33 -> -138.946 | J33: 26.243182 | K33: 51.865218 | L33: =B33*54.2221/B$137 -> 37.659564 | M33: =C33*100/C$137 -> 82.033406 | N33: =L33/M33 -> 0.45907595 | O33: 640.62465 | P33: 87.933192 | Q33: 541.88227 | R33: 351.80531
A34: 37377 | B34: 60.089024 | C34: 179.8 | D34: 577.29 | E34: 531.48 | F34: -45.81 | G34: 447.788 | H34: 531.8 | I34: =G34-H34 -> -84.012 | J34: 27.044545 | K34: 52.118906 | L34: =B34*54.2221/B$137 -> 37.843768 | M34: =C34*100/C$137 -> 82.033406 | N34: =L34/M34 -> 0.46132143 | O34: 531.47698 | P34: 130.95773 | Q34: 366.77679 | R34: 219.09005
A35: 37408 | B35: 60.31837 | C35: 179.9 | D35: 445.28 | E35: 522.96 | F35: 77.68 | G35: 407.292 | H35: 533.8 | I35: =G35-H35 -> -126.508 | J35: 25.5085 | K35: 52.317831 | L35: =B35*54.2221/B$137 -> 37.988209 | M35: =C35*100/C$137 -> 82.079031 | N35: =L35/M35 -> 0.46282477 | O35: 522.95648 | P35: 103.42 | Q35: 408.87317 | R35: 227.32935
A36: 37438 | B36: 60.278437 | C36: 180.1 | D36: 455.95 | E36: 543.8 | F36: 87.85 | G36: 421.499 | H36: 519.1 | I36: =G36-H36 -> -97.601 | J36: 26.92381 | K36: 52.283195 | L36: =B36*54.2221/B$137 -> 37.963059 | M36: =C36*100/C$137 -> 82.170281 | N36: =L36/M36 -> 0.46200474 | O36: 543.79836 | P36: 107.85223 | Q36: 398.05195 | R36: 248.91106
A37: 37469 | B37: 60.541779 | C37: 180.7 | D37: 549.18 | E37: 482.5 | F37: -66.68 | G37: 443.682 | H37: 571.3 | I37: =G37-H37 -> -127.618 | J37: 28.370455 | K37: 52.511608 | L37: =B37*54.2221/B$137 -> 38.128911 | M37: =C37*100/C$137 -> 82.44403 | N37: =L37/M37 -> 0.46248238 | O37: 482.49788 | P37: 125.19023 | Q37: 346.11475 | R37: 224.48867
A38: 37500 | B38: 60.890924 | C38: 181 | D38: 480.47 | E38: 621.47 | F38: 141 | G38: 447.007 | H38: 510.9 | I38: =G38-H38 -> -63.893 | J38: 29.67 | K38: 52.814442 | L38: =B38*54.2221/B$137 -> 38.3488 | M38: =C38*100/C$137 -> 82.580904 | N38: =L38/M38 -> 0.46437855 | O38: 621.46729 | P38: 148.37023 | Q38: 461.04229 | R38: 251.22467
A39: 37530 | B39: 61.283779 | C39: 181.3 | D39: 505.94 | E39: 607.49 | F39: 101.55 | G39: 428.504 | H39: 589.9 | I39: =G39-H39 -> -161.396 | J39: 28.85087 | K39: 53.15519 | L39: =B39*54.2221/B$137 -> 38.596218 | M39: =C39*100/C$137 -> 82.717779 | N39: =L39/M39 -> 0.46660124 | O39: 607.48556 | P39: 146.19523 | Q39: 449.91365 | R39: 233.85567
A40: 37561 | B40: 61.709552 | C40: 181.3 | D40: 637.7 | E40: 482.82 | F40: -154.88 | G40: 444.137 | H40: 481.5 | I40: =G40-H40 -> -37.363 | J40: 26.283158 | K40: 53.524489 | L40: =B40*54.2221/B$137 -> 38.864368 | M40: =C40*100/C$137 -> 82.717779 | N40: =L40/M40 -> 0.46984299 | O40: 482.82309 | P40: 111.66923 | Q40: 355.07112 | R40: 213.45317
A41: 37591 | B41: 61.921629 | C41: 180.9 | D41: 726.69 | E41: 491.46 | F41: -235.23 | G41: 445.81 | H41: 499.1 | I41: =G41-H41 -> -53.29 | J41: 29.435714 | K41: 53.708436 | L41: =B41*54.2221/B$137 -> 38.997933 | M41: =C41*100/C$137 -> 82.535279 | N41: =L41/M41 -> 0.47250017 | O41: 491.46232 | P41: 142.78223 | Q41: 359.07298 | R41: 260.48667
... A76: 38657 | B76: 68.851363 | C76: 197.6 | D76: 753.48 | E76: 761.15 | F76: 7.67 | G76: 897.14044 | H76: 972.7 | I76: =G76-H76 -> -75.55956 | J76: 58.283 | K76: 59.719021 | L76: =B76*54.2221/B$137 -> 43.362245 | M76: =C76*100/C$137 -> 90.154622 | N76: =L76/M76 -> 0.4809764 | O76: 761.15081 | P76: 195.51212 | Q76: 512.95154 | R76: 315.90876
A77: 38687 | B77: 69.056665 | C77: 196.8 | D77: 1113.64 | E77: 804.53 | F77: -309.11 | G77: 981.39005 | H77: 790.7 | I77: =G77-H77 -> 190.69005 | J77: 59.414286 | K77: 59.897092 | L77: =B77*54.2221/B$137 -> 43.491543 | M77: =C77*100/C$137 -> 89.789624 | N77: =L77/M77 -> 0.4843716 | O77: 804.53002 | P77: 86.789819 | Q77: 696.37014 | R77: 338.03519 | S77: =SUM(O153:O155) -> 0 | T77: =SUM(P153:P155) -> 0 | U77: =SUM(Q153:Q155) -> 0 | V77: =SUM(R153:R155) -> 0
A78: 38718 | B78: 69.386835 | C78: 198.3 | D78: 591.91 | E78: 965.68 | F78: 373.77 | G78: 1023.2616 | H78: 827.8 | I78: =G78-H78 -> 195.4616 | J78: 65.4835 | K78: 60.183469 | L78: =B78*54.2221/B$137 -> 43.699483 | M78: =C78*100/C$137 -> 90.473996 | N78: =L78/M78 -> 0.483006 | O78: 965.68623 | P78: 291.76078 | Q78: 658.03129 | R78: 412.20943
A79: 38749 | B79: 69.87796 | C79: 198.7 | D79: 751.49 | E79: 631.88 | F79: -119.61 | G79: 947.89876 | H79: 710.6 | I79: =G79-H79 -> 237.29876 | J79: 61.615263 | K79: 60.609452 | L79: =B79*54.2221/B$137 -> 44.008791 | M79: =C79*100/C$137 -> 90.656495 | N79: =L79/M79 -> 0.48544554 | O79: 631.88142 | P79: 206.912 | Q79: 425.54179 | R79: 251.86427
A80: 38777 | B80: 70.333289 | C80: 199.8 | D80: 872.49 | E80: 944.38 | F80: 71.89 | G80: 1058.5531 | H80: 989.9 | I80: =G80-H80 -> 68.6531 | J80: 62.889565 | K80: 61.004387 | L80: =B80*54.2221/B$137 -> 44.295555 | M80: =C80*100/C$137 -> 91.158368 | N80: =L80/M80 -> 0.48591869 | O80: 944.37881 | P80: 232.84809 | Q80: 681.41926 | R80: 375.88433 | S80: =SUM(O156:O158) -> 0 | T80: =SUM(P156:P158) -> 0 | U80: =SUM(Q156:Q158) -> 0 | V80: =SUM(R156:R158) -> 0
A81: 38808 | B81: 70.38145 | C81: 201.5 | D81: 727.77 | E81: 1131.54 | F81: 403.77 | G81: 1176.7875 | H81: 852.1 | I81: =G81-H81 -> 324.68752 | J81: 69.412778 | K81: 61.04616 | L81: =B81*54.2221/B$137 -> 44.325887 | M81: =C81*100/C$137 -> 91.93399 | N81: =L81/M81 -> 0.48214906 | O81: 1131.5403 | P81: 223.011 | Q81: 994.34731 | R81: 757.62769
A82: 38838 | B82: 70.284315 | C82: 202.5 | D82: 793.5 | E82: 1100.05 | F82: 306.55 | G82: 1086.7671 | H82: 1015.5 | I82: =G82-H82 -> 71.26712 | J82: 70.933182 | K82: 60.961909 | L82: =B82*54.2221/B$137 -> 44.264711 | M82: =C82*100/C$137 -> 92.390238 | N82: =L82/M82 -> 0.47910594 | O82: 1100.0516 | P82: 365.32689 | Q82: 712.2577 | R82: 408.51326
A83: 38869 | B83: 70.122692 | C83: 202.9 | D83: 822.22 | E83: 867.05 | F83: 44.83 | G83: 1059.5297 | H83: 874.2 | I83: =G83-H83 -> 185.32967 | J83: 70.931818 | K83: 60.821723 | L83: =B83*54.2221/B$137 -> 44.162922 | M83: =C83*100/C$137 -> 92.572737 | N83: =L83/M83 -> 0.47706186 | O83: 867.04725 | P83: 239.01207 | Q83: 680.00231 | R83: 358.80179 | S83: =SUM(O159:O161) -> 0 | T83: =SUM(P159:P161) -> 0 | U83: =SUM(Q159:Q161) -> 0 | V83: =SUM(R159:R161) -> 0
A84: 38899 | B84: 70.143546 | C84: 203.5 | D84: 723.49 | E84: 902.16 | F84: 178.67 | G84: 1041.9202 | H84: 971 | I84: =G84-H84 -> 70.9202 | J84: 74.404211 | K84: 60.839811 | L84: =B84*54.2221/B$137 -> 44.176056 | M84: =C84*100/C$137 -> 92.846486 | N84: =L84/M84 -> 0.47579675 | O84: 902.1569 | P84: 277.40278 | Q84: 655.70928 | R84: 448.18765
A85: 38930 | B85: 70.294099 | C85: 203.9 | D85: 873.06 | E85: 758.16 | F85: -114.9 | G85: 1127.6715 | H85: 998.2 | I85: =G85-H85 -> 129.47152 | J85: 73.041739 | K85: 60.970394 | L85: =B85*54.2221/B$137 -> 44.270873 | M85: =C85*100/C$137 -> 93.028985 | N85: =L85/M85 -> 0.47588257 | O85: 758.16661 | P85: 197.26423 | Q85: 594.32739 | R85: 374.30821
A86: 38961 | B86: 70.696813 | C86: 202.9 | D86: 796.16 | E86: 794.35 | F86: -1.81 | G86: 1096.9109 | H86: 1048 | I86: =G86-H86 -> 48.91086 | J86: 63.819 | K86: 61.319693 | L86: =B86*54.2221/B$137 -> 44.524501 | M86: =C86*100/C$137 -> 92.572737 | N86: =L86/M86 -> 0.48096774 | O86: 794.35046 | P86: 72.342065 | Q86: 764.03796 | R86: 446.20029 | S86: =SUM(O162:O164) -> 0 | T86: =SUM(P162:P164) -> 0 | U86: =SUM(Q162:Q164) -> 0 | V86: =SUM(R162:R164) -> 0
A87: 38991 | B87: 70.943382 | C87: 201.8 | D87: 811.2 | E87: 1318.26 | F87: 507.06 | G87: 1051.8995 | H87: 1084.1 | I87: =G87-H87 -> -32.20052 | J87: 58.850455 | K87: 61.533558 | L87: =B87*54.2221/B$137 -> 44.679788 | M87: =C87*100/C$137 -> 92.070864 | N87: =L87/M87 -> 0.48527608 | O87: 1318.2641 | P87: 638.04295 | Q87: 681.3346 | R87: 358.81112
A88: 39022 | B88: 71.060782 | C88: 201.5 | D88: 897.86 | E88: 993.08 | F88: 95.22 | G88: 1044.3057 | H88: 988.1 | I88: =G88-H88 -> 56.20567 | J88: 59.1305 | K88: 61.635386 | L88: =B88*54.2221/B$137 -> 44.753726 | M88: =C88*100/C$137 -> 91.93399 | N88: =L88/M88 -> 0.48680283 | O88: 993.08067 | P88: 332.80702 | Q88: 672.04322 | R88: 384.60876
...

Sheet Data sa
A1: date | B1: año | C1: mes | D1: v_1 | E1: v_2 | F1: v_3 | G1: v_4 | H1: v_5 | I1: v_6 | J1: v_7 | K1: v_8 | L1: v_9 | M1: v_11
A2: 37257 | B2: =YEAR(A2) -> 2002 | C2: =MONTH(A2) -> 1 | D2: 57.756016 | E2: 177.99343 | F2: 502.7649 | G2: 500.00698 | H2: -34.234354 | I2: 356.96195 | J2: 467.56369 | K2: -59.432794 | L2: 19.54338 | M2: 50.095344 | O2: 37257
A3: 37288 | B3: =YEAR(A3) -> 2002 | C3: =MONTH(A3) -> 2 | D3: 58.174537 | E3: 178.06952 | F3: 463.28569 | G3: 563.74048 | H3: 97.56345 | I3: 372.88136 | J3: 468.72476 | K3: -102.09906 | L3: 22.03949 | M3: 50.458353 | O3: 37288
A4: 37316 | B4: =YEAR(A4) -> 2002 | C4: =MONTH(A4) -> 3 | D4: 58.676633 | E4: 178.4295 | F4: 448.1338 | G4: 484.8317 | H4: -13.871439 | I4: 399.93916 | J4: 472.38134 | K4: -87.420008 | L4: 22.923641 | M4: 50.893852 | O4: 37316
A5: 37347 | B5: =YEAR(A5) -> 2002 | C5: =MONTH(A5) -> 4 | D5: 59.250983 | E5: 179.15807 | F5: 536.63638 | G5: 521.50959 | H5: -53.616519 | I5: 418.38742 | J5: 614.98407 | K5: -139.74049 | L5: 26.702077 | M5: 51.392021 | O5: 37347
A6: 37377 | B6: =YEAR(A6) -> 2002 | C6: =MONTH(A6) -> 5 | D6: 59.716022 | E6: 179.31168 | F6: 541.13084 | G6: 513.69375 | H6: 2.3176279 | I6: 441.92805 | J6: 489.69887 | K6: -30.24629 | L6: 26.786171 | M6: 51.795378 | O6: 37377
A7: 37408 | B7: =YEAR(A7) -> 2002 | C7: =MONTH(A7) -> 6 | D7: 60.205417 | E7: 179.51769 | F7: 487.64222 | G7: 565.86846 | H7: 32.125814 | I7: 407.5848 | J7: 548.33678 | K7: -200.9749 | L7: 26.005562 | M7: 52.219861 | O7: 37408
A8: 37438 | B8: =YEAR(A8) -> 2002 | C8: =MONTH(A8) -> 7 | D8: 60.501357 | E8: 179.95772 | F8: 499.63712 | G8: 497.00187 | H8: 4.900056 | I8: 427.8449 | J8: 500.99663 | K8: -60.527602 | L8: 26.560429 | M8: 52.476547 | O8: 37438
A9: 37469 | B9: =YEAR(A9) -> 2002 | C9: =MONTH(A9) -> 8 | D9: 60.875758 | E9: 180.45407 | F9: 509.08438 | G9: 508.96355 | H9: -6.8369928 | I9: 429.14876 | J9: 557.9492 | K9: -142.64449 | L9: 25.983801 | M9: 52.801288 | O9: 37469
A10: 37500 | B10: =YEAR(A10) -> 2002 | C10: =MONTH(A10) -> 9 | D10: 61.079506 | E10: 180.58474 | F10: 504.31117 | G10: 579.736 | H10: 80.841258 | I10: 438.01722 | J10: 546.70736 | K10: -144.87208 | L10: 28.316634 | M10: 52.978011 | O10: 37500
A11: 37530 | B11: =YEAR(A11) -> 2002 | C11: =MONTH(A11) -> 10 | D11: 61.463923 | E11: 180.99426 | F11: 532.05552 | G11: 593.22535 | H11: 38.905535 | I11: 424.70509 | J11: 515.40079 | K11: -83.360329 | L11: 28.654307 | M11: 53.31144 | O11: 37530
A12: 37561 | B12: =YEAR(A12) -> 2002 | C12: =MONTH(A12) -> 11 | D12: 61.808325 | E12: 181.73576 | F12: 617.08961 | G12: 531.14899 | H12: -46.484336 | I12: 459.71339 | J12: 483.43281 | K12: -9.6782097 | L12: 27.518206 | M12: 53.610161 | O12: 37561
A13: 37591 | B13: =YEAR(A13) -> 2002 | C13: =MONTH(A13) -> 12 | D13: 62.141134 | E13: 182.23688 | F13: 507.98642 | G13: 532.27912 | H13: 102.00672 | I13: 456.39376 | J13: 505.87798 | K13: -57.323054 | L13: 31.85431 | M13: 53.898827 | O13: 37591
... A231: 44228 | B231: =YEAR(A231) -> 2021 | C231: =MONTH(A231) -> 2 | D231: 104.49261 | E231: 263.66785 | F231: 2925.8166 | G231: 2979.5982 | H231: -190.59036 | I231: 2022.5131 | J231: 1719.4039 | K231: 293.75954 | L231: 57.866584 | M231: 90.632865 | O231: 44228
A232: 44256 | B232: =YEAR(A232) -> 2021 | C232: =MONTH(A232) -> 3 | D232: 104.70458 | E232: 264.8226 | F232: 3612.2328 | I232: 2016.4714 | J232: 1951.3071 | K232: 161.84995 | L232: 62.848589 | M232: 90.816719 | O232: 44256
A233: 44287 | B233: =YEAR(A233) -> 2021 | C233: =MONTH(A233) -> 4 | D233: 104.85604 | E233: 266.77606 | F233: 3215.4568 | I233: 2181.7315 | J233: 1776.6011 | K233: 401.49525 | L233: 60.55542 | M233: 90.948091 | O233: 44287
A234: 44317 | B234: =YEAR(A234) -> 2021 | C234: =MONTH(A234) -> 5 | D234: 104.91954 | E234: 268.41067 | F234: 3566.8181 | I234: 2128.4977 | J234: 1845.5121 | K234: 315.81859 | L234: 64.236454 | M234: 91.003172 | O234: 44317
A235: 44348 | B235: =YEAR(A235) -> 2021 | C235: =MONTH(A235) -> 6 | D235: 104.88605 | E235: 270.62988 | F235: 3409.4438 | I235: 2228.2992 | J235: 1934.2751 | K235: 285.81637 | L235: 68.705994 | M235: 90.974121 | O235: 44348
A236: 44378 | B236: =YEAR(A236) -> 2021 | C236: =MONTH(A236) -> 7 | D236: 105.32015 | E236: 272.05819 | F236: 3429.8384 | I236: 2264.1238 | J236: 2125.0654 | K236: 115.89963 | L236: 69.944723 | M236: 91.350639 | O236: 44378
A237: 44409 | B237: =YEAR(A237) -> 2021 | C237: =MONTH(A237) -> 8 | D237: 105.5211 | E237: 272.98778 | F237: 3424.5052 | I237: 2247.8702 | J237: 2150.1698 | K237: 85.512184 | L237: 67.642343 | M237: 91.524942 | O237: 44409
A238: 44440 | B238: =YEAR(A238) -> 2021 | C238: =MONTH(A238) -> 9 | D238: 105.49511 | E238: 273.99862 | F238: 3205.2138 | I238: 2364.164 | J238: 2022.8764 | K238: 292.87733 | L238: 73.106886 | M238: 91.502394 | O238: 44440
A239: 44470 | B239: =YEAR(A239) -> 2021 | C239: =MONTH(A239) -> 10 | D239: 105.80317 | E239: 276.45088 | F239: 3241.2414 | I239: 2562.7463 | J239: 2093.3298 | K239: 497.03555 | L239: 80.572058 | M239: 91.769592 | O239: 44470
A240: 44501 | B240: =YEAR(A240) -> 2021 | C240: =MONTH(A240) -> 11 | D240: 106.30996 | E240: 278.75689 | F240: 3330.7261 | I240: 2617.4277 | J240: 2194.9542 | K240: 398.12326 | L240: 80.531835 | M240: 92.209163 | O240: 44501
A241: 44531 | B241: =YEAR(A241) -> 2021 | C241: =MONTH(A241) -> 12 | D241: 106.4348 | E241: 280.46875 | F241: 3572.6048 | I241: 2132.5733 | J241: 2285.5038 | K241: -170.85872 | L241: 75.987808 | M241: 92.317444 | O241: 44531
A242: 44562 | B242: =YEAR(A242) -> 2022 | C242: =MONTH(A242) -> 1 | D242: 107.06388 | E242: 282.37778 | F242: 3456.5112 | I242: 2625.2576 | J242: 2469.3634 | K242: 104.61216 | L242: 85.232867 | M242: 92.863085 | O242: 44562
A243: 44593 | B243: =YEAR(A243) -> 2022 | C243: =MONTH(A243) -> 2 | D243: 107.38148 | E243: 284.39898 | F243: 3661.655 | I243: 2738.577 | J243: 2457.7017 | K243: 347.59582 | L243: 90.978022 | M243: 93.138559 | O243: 44593
... A263: 45200 | B263: =YEAR(A263) -> 2023 | C263: =MONTH(A263) -> 10 | D263: 112.08635 | E263: 307.60709 | F263: 4147.435 | I263: 2609.7386 | J263: 2496.9978 | K263: 65.104756 | L263: 83.612444 | M263: 97.219385 | O263: 45200
A264: 45231 | B264: =YEAR(A264) -> 2023 | C264: =MONTH(A264) -> 11 | D264: 111.85196 | E264: 308.05403 | F264: 4302.7387 | J264: 2425.5391 | K264: -2423.8203 | L264: 78.719847 | M264: 97.016083 | O264: 45231
A265: 45261 | B265: =YEAR(A265) -> 2023 | C265: =MONTH(A265) -> 12 | D265: 111.91455 | E265: 308.67235 | F265: 3568.481 | J265: 2355.4135 | K265: -2306.205 | L265: 77.242455 | M265: 97.070371 | O265: 45261
A266: 45292 | B266: =YEAR(A266) -> 2024 | C266: =MONTH(A266) -> 1 | D266: 111.95551 | E266: 309.82308 | F266: 4108.0622 | J266: 2195.4605 | K266: -2080.0784 | L266: 76.860814 | M266: 97.105896 | O266: 45292
A267: 45323 | B267: =YEAR(A267) -> 2024 | C267: =MONTH(A267) -> 2 | D267: 112.13649 | E267: 310.97504 | J267: 2173.0038 | K267: -2153.8055 | L267: 77.497739 | M267: 97.262873 | O267: 45323

Sheet Data trim
A1: fecha | B1: v_1 | C1: v_2 | D1: v_3 | E1: V_3 (P) | F1: V_4(P) | G1: V_3/V_4 | H1: V_3/V_10 | I1: v_4 | J1: v_5 | K1: v_6 | L1: v_7 | M1: v_8 | N1: v_9 | O1: v_10 | P1: v_11 | Q1: V_38 | R1: V_39 | T1: V_40 | U1: V_41 | V1: V_42 | W1: Cuenta Corriente | X1: Exportaciones (bienes) | Y1: Importaciones (bienes) | Z1: Exportaciones (servicios) | AA1: Importaciones (servicios) | AB1: Exportaciones (bienes + servicios) | AC1: Importaciones (bienes + servicios) | AD1: Balanza Comercial | AE1: Crédito (Renta recibida) | AF1: Débito (Renta pagada) | AG1: Crédito (transf. recibida) | AH1: Débito (transf. pagada) | AI1: Crédito (Transferencias de capital recibidas) | AJ1: Debito (Transferencias de capital enviadas) | AK1: Total ingresos | AL1: Ingresos Petroleros | AM1: Ingresos no petroleros | AN1: Ingresos tributarios | AQ1: ingres sec
A2: 36495 | Q2: =AVERAGE(Data!L3:L5) -> 14.423665 | R2: =AVERAGE(Data!M3:M5) -> 76.771345
A3: 36586 | Q3: =AVERAGE(Data!L6:L8) -> 19.08564 | R3: =AVERAGE(Data!M6:M8) -> 77.531759 | T3: 11973785
A4: 36678 | Q4: =AVERAGE(Data!L9:L11) -> 23.946546 | R4: =AVERAGE(Data!M9:M11) -> 78.353005 | T4: 12435932
A5: 36770 | Q5: =AVERAGE(Data!L12:L14) -> 26.335537 | R5: =AVERAGE(Data!M12:M14) -> 78.976544 | T5: 13192816
A6: 36861 | Q6: =AVERAGE(Data!L15:L17) -> 28.458756 | R6: =AVERAGE(Data!M15:M17) -> 79.402376 | T6: 14555506
A7: 36951 | Q7: =AVERAGE(Data!L18:L20) -> 31.994435 | R7: =AVERAGE(Data!M18:M20) -> 80.162789 | T7: 12757885
A8: 37043 | Q8: =AVERAGE(Data!L21:L23) -> 33.419582 | R8: =AVERAGE(Data!M21:M23) -> 80.999244 | T8: 13167471
A9: 37135 | Q9: =AVERAGE(Data!L24:L26) -> 33.953162 | R9: =AVERAGE(Data!M24:M26) -> 81.105702 | T9: 13455244
A10: 37226 | Q10: =AVERAGE(Data!L27:L29) -> 35.317134 | R10: =AVERAGE(Data!M27:M29) -> 80.877578 | T10: 14971349
A11: 37316 | B11: 58.202395 | C11: 178.16415 | D11: =SUM(Data!C30:C32) -> 533.7 | E11: =SUM(Data!D30:D32) -> 1265.54 | F11: =SUM(Data!E30:E32) -> 1436.29 | G11: =E11/F11 -> 0.88111732 | H11: =E11/O11 -> 0.20897244 | I11: 1548.5792 | J11: 49.457657 | K11: 1129.7825 | L11: 1408.6698 | M11: -248.95186 | N11: 21.502171 | O11: 6056.014 | P11: 50.482517 | Q11: =AVERAGE(Data!L30:L32) -> 36.700818 | R11: =AVERAGE(Data!M30:M32) -> 81.166535 | T11: 13314495 | U11: =AB11+AE11+AG11 -> 1774.3934 | V11: =AC11+AF11+AH11 -> 2065.3866 | W11: =U11/V11 -> 0.85910958 | X11: 1151.5991 | Y11: 1370.6946 | Z11: 211.39039 | AA11: 380.463 | AB11: =X11+Z11 -> 1362.9895 | AC11: =Y11+AA11 -> 1751.1576 | AD11: =AB11/AC11 -> 0.77833632 | AE11: 23.482903 | AF11: 300.206 | AG11: 387.92101 | AH11: 14.023082 | AI11: 7.023 | AJ11: 2 | AK11: 1436.2838 | AL11: 288.391 | AM11: 1094.1135 | AN11: 675.65792 | AQ11: =AG11-AH11 -> 373.89793
A12: 37408 | B12: 59.724141 | C12: 179.32914 | D12: =SUM(Data!C33:C35) -> 539.5 | E12: =SUM(Data!D33:D35) -> 1539.71 | F12: =SUM(Data!E33:E35) -> 1695.06 | G12: =E12/F12 -> 0.90835133 | H12: =E12/O12 -> 0.23939528 | I12: 1601.0718 | J12: -19.173077 | K12: 1267.9003 | L12: 1653.0197 | M12: -370.96169 | N12: 26.497936 | O12: 6431.664 | P12: 51.80242 | Q12: =AVERAGE(Data!L33:L35) -> 37.830514 | R12: =AVERAGE(Data!M33:M35) -> 82.048615 | T12: 13815664 | U12: =AB12+AE12+AG12 -> 2009.0829 | V12: =AC12+AF12+AH12 -> 2417.206 | W12: =U12/V12 -> 0.83115912 | X12: 1355.4692 | Y12: 1670.2517 | Z12: 222.88434 | AA12: 406.129 | AB12: =X12+Z12 -> 1578.3535 | AC12: =Y12+AA12 -> 2076.3807 | AD12: =AB12/AC12 -> 0.76014651 | AE12: 23.08355 | AF12: 326.39902 | AG12: 407.6458 | AH12: 14.426365 | AI12: 11.68 | AJ12: 2 | AK12: 1695.0581 | AL12: 322.31092 | AM12: 1317.5322 | AN12: 798.22471 | AQ12: =AG12-AH12 -> 393.21943
A13: 37500 | B13: 60.818873 | C13: 180.33218 | D13: =SUM(Data!C36:C38) -> 541.8 | E13: =SUM(Data!D36:D38) -> 1485.6 | F13: =SUM(Data!E36:E38) -> 1647.77 | G13: =E13/F13 -> 0.90158214 | H13: =E13/O13 -> 0.21710646 | I13: 1585.7014 | J13: 78.904321 | K13: 1295.0109 | L13: 1605.6532 | M13: -348.04417 | N13: 26.953621 | O13: 6842.726 | P13: 52.751949 | Q13: =AVERAGE(Data!L36:L38) -> 38.146923 | R13: =AVERAGE(Data!M36:M38) -> 82.398405 | T13: 14177884 | U13: =AB13+AE13+AG13 -> 2050.245 | V13: =AC13+AF13+AH13 -> 2380.413 | W13: =U13/V13 -> 0.86129801 | X13: 1370.7106 | Y13: 1605.0032 | Z13: 228.02734 | AA13: 409.50801 | AB13: =X13+Z13 -> 1598.7379 | AC13: =Y13+AA13 -> 2014.5112 | AD13: =AB13/AC13 -> 0.79361085 | AE13: 18.803823 | AF13: 351.17758 | AG13: 432.7032 | AH13: 14.72421 | AI13: 7.9061 | AJ13: 2 | AK13: 1647.7635 | AL13: 381.41268 | AM13: 1205.209 | AN13: 724.62439 | AQ13: =AG13-AH13 -> 417.97899
A14: 37591 | B14: 61.804461 | C14: 181.65563 | D14: =SUM(Data!C39:C41) -> 543.5 | E14: =SUM(Data!D39:D41) -> 1870.33 | F14: =SUM(Data!E39:E41) -> 1581.77 | G14: =E14/F14 -> 1.1824285 | H14: =E14/O14 -> 0.24215172 | I14: 1656.6535 | J14: 94.427915 | K14: 1340.8122 | L14: 1504.7116 | M14: -150.36159 | N14: 29.342274 | O14: 7723.794 | P14: 53.606809 | Q14: =AVERAGE(Data!L39:L41) -> 38.819507 | R14: =AVERAGE(Data!M39:M41) -> 82.656946 | T14: 15722423 | U14: =AB14+AE14+AG14 -> 2100.0964 | V14: =AC14+AF14+AH14 -> 2289.8368 | W14: =U14/V14 -> 0.91713799 | X14: 1379.9038 | Y14: 1513.7339 | Z14: 221.62015 | AA14: 403.75953 | AB14: =X14+Z14 -> 1601.5239 | AC14: =Y14+AA14 -> 1917.4934 | AD14: =AB14/AC14 -> 0.83521743 | AE14: 17.345296 | AF14: 357.69517 | AG14: 481.22717 | AH14: 14.648272 | AI14: 8.0124 | AJ14: 2 | AK14: 1581.771 | AL14: 400.64668 | AM14: 1164.0577 | AN14: 707.79551 | AQ14: =AG14-AH14 -> 466.57889
A15: 37681 | B15: 63.828736 | C15: 183.32684 | D15: =SUM(Data!C42:C44) -> 549 | E15: =SUM(Data!D42:D44) -> 1371.55 | F15: =SUM(Data!E42:E44) -> 1605.61 | G15: =E15/F15 -> 0.85422363 | H15: =E15/O15 -> 0.18876884 | I15: 1660.0542 | J15: 129.03939 | K15: 1578.2739 | L15: 1558.141 | M15: 23.470858 | N15: 34.220287 | O15: 7265.765 | P15: 55.362587 | Q15: =AVERAGE(Data!L42:L44) -> 40.246919 | R15: =AVERAGE(Data!M42:M44) -> 83.4934 | S15: =Q15/R15 -> 0.48203713 | T15: 13903569 | U15: =AB15+AE15+AG15 -> 2245.7663 | V15: =AC15+AF15+AH15 -> 2311.1223 | W15: =U15/V15 -> 0.9717211 | X15: 1595.3812 | Y15: 1522.2151 | Z15: 214.01448 | AA15: 414.20099 | AB15: =X15+Z15 -> 1809.3957 | AC15: =Y15+AA15 -> 1936.4161 | AD15: =AB15/AC15 -> 0.93440435 | AE15: 14.834026 | AF15: 373.97457 | AG15: 421.53665 | AH15: 0.73162719 | AI15: 38.481306 | AJ15: 2.25 | AK15: 1605.601 | AL15: 433.8 | AM15: 1170.6882 | AN15: 742.47423 | AQ15: =AG15-AH15 -> 420.80502
A16: 37773 | B16: 64.633307 | C16: 183.12823 | D16: =SUM(Data!C45:C47) -> 551 | E16: =SUM(Data!D45:D47) -> 1543.38 | F16: =SUM(Data!E45:E47) -> 1729.48 | G16: =E16/F16 -> 0.8923954 | H16: =E16/O16 -> 0.2130273 | I16: 1629.4442 | J16: -22.178987 | K16: 1398.0534 | L16: 1518.0399 | M16: -124.02211 | N16: 29.11772 | O16: 7244.987 | P16: 56.060442 | Q16: =AVERAGE(Data!L45:L47) -> 40.913838 | R16: =AVERAGE(Data!M45:M47) -> 83.797566 | S16: =Q16/R16 -> 0.48824614 | T16: 13983215 | U16: =AB16+AE16+AG16 -> 2153.8545 | V16: =AC16+AF16+AH16 -> 2388.6216 | W16: =U16/V16 -> 0.9017144 | X16: 1491.9231 | Y16: 1549.9584 | Z16: 222.951 | AA16: 408.24909 | AB16: =X16+Z16 -> 1714.8741 | AC16: =Y16+AA16 -> 1958.2075 | AD16: =AB16/AC16 -> 0.87573668 | AE16: 14.806015 | AF16: 429.18659 | AG16: 424.17435 | AH16: 1.227534 | AI16: 17.331481 | AJ16: 2.25 | AK16: 1729.4724 | AL16: 313.17 | AM16: 1345.1343 | AN16: 857.61781 | AQ16: =AG16-AH16 -> 422.94682
A17: 37865 | B17: 65.371558 | C17: 184.23369 | D17: =SUM(Data!C48:C50) -> 553.7 | E17: =SUM(Data!D48:D50) -> 1769.94 | F17: =SUM(Data!E48:E50) -> 1821.85 | G17: =E17/F17 -> 0.97150698 | H17: =E17/O17 -> 0.23022529 | I17: 1823.3319 | J17: -15.561742 | K17: 1518.8011 | L17: 1563.724 | M17: -69.908429 | N17: 28.445305 | O17: 7687.861 | P17: 56.700773 | Q17: =AVERAGE(Data!L48:L50) -> 41.019308 | R17: =AVERAGE(Data!M48:M50) -> 84.208189 | S17: =Q17/R17 -> 0.4871178 | T17: 14456706 | U17: =AB17+AE17+AG17 -> 2278.91 | V17: =AC17+AF17+AH17 -> 2404.3784 | W17: =U17/V17 -> 0.94781669 | X17: 1592.6364 | Y17: 1615.864 | Z17: 224.56463 | AA17: 401.94556 | AB17: =X17+Z17 -> 1817.201 | AC17: =Y17+AA17 -> 2017.8095 | AD17: =AB17/AC17 -> 0.90058106 | AE17: 15.090307 | AF17: 367.70298 | AG17: 446.61867 | AH17: 18.865925 | AI17: 6.0976031 | AJ17: 2.25 | AK17: 1821.8473 | AL17: 460.2 | AM17: 1315.3455 | AN17: 793.84303 | AQ17: =AG17-AH17 -> 427.75274
A18: 37956 | B18: 65.786431 | C18: 185.11683 | D18: =SUM(Data!C51:C53) -> 553.8 | E18: =SUM(Data!D51:D53) -> 1901.69 | F18: =SUM(Data!E51:E53) -> 1753.32 | G18: =E18/F18 -> 1.0846223 | H18: =E18/O18 -> 0.21692456 | I18: 1772.9298 | J18: 250.49875 | K18: 1741.3533 | L18: 1603.9148 | M18: 180.88873 | N18: 32.500919 | O18: 8766.596 | P18: 57.060617 | Q18: =AVERAGE(Data!L51:L53) -> 41.330507 | R18: =AVERAGE(Data!M51:M53) -> 84.223397 | S18: =Q18/R18 -> 0.49072476 | T18: 16332020 | U18: =AB18+AE18+AG18 -> 2502.2959 | V18: =AC18+AF18+AH18 -> 2463.5228 | W18: =U18/V18 -> 1.0157389 | X18: 1765.8862 | Y18: 1678.2892 | Z18: 219.62189 | AA18: 400.08281 | AB18: =X18+Z18 -> 1985.5081 | AC18: =Y18+AA18 -> 2078.372 | AD18: =AB18/AC18 -> 0.95531892 | AE18: 17.840147 | AF18: 384.12446 | AG18: 498.94762 | AH18: 1.0263901 | AI18: 7.6914874 | AJ18: 2.25 | AK18: 1753.3222 | AL18: 456.48274 | AM18: 1324.7047 | AN18: 769.58142 | AQ18: =AG18-AH18 -> 497.92123
A19: 38047 | B19: 66.326534 | C19: 186.71285 | D19: =SUM(Data!C54:C56) -> 558.8 | E19: =SUM(Data!D54:D56) -> 1632.95 | F19: =SUM(Data!E54:E56) -> 1842.54 | G19: =E19/F19 -> 0.88624942 | H19: =E19/O19 -> 0.20202629 | I19: 1918.7608 | J19: 118.21221 | K19: 1739.4882 | L19: 1660.7248 | M19: 67.673952 | N19: 36.038825 | O19: 8082.859 | P19: 57.529081 | Q19: =AVERAGE(Data!L54:L56) -> 41.821944 | R19: =AVERAGE(Data!M54:M56) -> 84.983811 | S19: =Q19/R19 -> 0.49211661 | T19: 14557303 | U19: =AB19+AE19+AG19 -> 2467.8755 | V19: =AC19+AF19+AH19 -> 2495.7873 | W19: =U19/V19 -> 0.98881643 | X19: 1743.6109 | Y19: 1600.8622 | Z19: 238.21343 | AA19: 465.94281 | AB19: =X19+Z19 -> 1981.8244 | AC19: =Y19+AA19 -> 2066.805 | AD19: =AB19/AC19 -> 0.9588831 | AE19: 17.030222 | AF19: 427.86045 | AG19: 469.02095 | AH19: 1.1218982 | AI19: 5.3967888 | AJ19: 2.5 | AK19: 1842.5486 | AL19: 429.85925 | AM19: 1315.7296 | AN19: 806.25362 | AQ19: =AG19-AH19 -> 467.89905
A20: 38139 | B20: 66.716009 | C20: 188.31622 | D20: =SUM(Data!C57:C59) -> 566.8 | E20: =SUM(Data!D57:D59) -> 1861.73 | F20: =SUM(Data!E57:E59) -> 2046.84 | G20: =E20/F20 -> 0.90956303 | H20: =E20/O20 -> 0.22364093 | I20: 1936.3442 | J20: -74.062393 | K20: 1932.1572 | L20: 1832.0244 | M20: 93.511676 | N20: 38.115748 | O20: 8324.639 | P20: 57.866897 | Q20: =AVERAGE(Data!L57:L59) -> 42.209045 | R20: =AVERAGE(Data!M57:M59) -> 86.200472 | S20: =Q20/R20 -> 0.48966141 | T20: 15036628 | U20: =AB20+AE20+AG20 -> 2814.7435 | V20: =AC20+AF20+AH20 -> 2819.2682 | W20: =U20/V20 -> 0.99839508 | X20: 2040.8013 | Y20: 1825.2247 | Z20: 261.15232 | AA20: 482.25715 | AB20: =X20+Z20 -> 2301.9536 | AC20: =Y20+AA20 -> 2307.4818 | AD20: =AB20/AC20 -> 0.99760422 | AE20: 22.132583 | AF20: 509.01548 | AG20: 490.65734 | AH20: 2.7709221 | AI20: 5.6165501 | AJ20: 2.5 | AK20: 2046.8497 | AL20: 500.9802 | AM20: 1486.8394 | AN20: 974.15578 | AQ20: =AG20-AH20 -> 487.88642
A21: 38231 | B21: 66.640867 | C21: 189.16226 | D21: =SUM(Data!C60:C62) -> 568.8 | E21: =SUM(Data!D60:D62) -> 1835.44 | F21: =SUM(Data!E60:E62) -> 2167.83 | G21: =E21/F21 -> 0.84667156 | H21: =E21/O21 -> 0.20818239 | I21: 2135.4849 | J21: 282.15273 | K21: 2002.3963 | L21: 1896.6952 | M21: 92.091342 | N21: 41.482443 | O21: 8816.5 | P21: 57.801722 | Q21: =AVERAGE(Data!L60:L62) -> 41.835765 | R21: =AVERAGE(Data!M60:M62) -> 86.504638 | S21: =Q21/R21 -> 0.48362454 | T21: 15584558 | U21: =AB21+AE21+AG21 -> 2894.67 | V21: =AC21+AF21+AH21 -> 2903.6371 | W21: =U21/V21 -> 0.99691176 | X21: 2092.6662 | Y21: 1963.3582 | Z21: 262.83016 | AA21: 499.05077 | AB21: =X21+Z21 -> 2355.4964 | AC21: =Y21+AA21 -> 2462.409 | AD21: =AB21/AC21 -> 0.9565821 | AE21: 26.454552 | AF21: 427.34881 | AG21: 512.71903 | AH21: 13.879282 | AI21: 6.0145196 | AJ21: 2.5 | AK21: 2167.8269 | AL21: 610.85421 | AM21: 1499.185 | AN21: 911.10149 | AQ21: =AG21-AH21 -> 498.83975
A22: 38322 | B22: 67.057985 | C22: 191.29958 | D22: =SUM(Data!C63:C65) -> 572.2 | E22: =SUM(Data!D63:D65) -> 2163.01 | F22: =SUM(Data!E63:E65) -> 2119.25 | G22: =E22/F22 -> 1.0206488 | H22: =E22/O22 -> 0.21693119 | I22: 2197.4753 | J22: 399.84056 | K22: 2071.6994 | L22: 2113.538 | M22: -14.101187 | N22: 49.827548 | O22: 9970.95 | P22: 58.163514 | Q22: =AVERAGE(Data!L63:L65) -> 42.129291 | R22: =AVERAGE(Data!M63:M65) -> 87.021719 | S22: =Q22/R22 -> 0.48412387 | T22: 17505965 | U22: =AB22+AE22+AG22 -> 2953.236 | V22: =AC22+AF22+AH22 -> 3391.2551 | W22: =U22/V22 -> 0.87083865 | X22: 2090.6752 | Y22: 2294.3024 | Z22: 251.75398 | AA22: 520.31557 | AB22: =X22+Z22 -> 2342.4292 | AC22: =Y22+AA22 -> 2814.618 | AD22: =AB22/AC22 -> 0.83223699 | AE22: 34.506774 | AF22: 575.93199 | AG22: 576.30008 | AH22: 0.70515148 | AI22: 6.8226907 | AJ22: 2.5 | AK22: 2119.2513 | AL22: 573.692 | AM22: 1522.9986 | AN22: 903.35789 | AQ22: =AG22-AH22 -> 575.59493
A23: 38412 | B23: 67.227554 | C23: 192.55143 | D23: =SUM(Data!C66:C68) -> 575.8 | E23: =SUM(Data!D66:D68) -> 1959.28 | F23: =SUM(Data!E66:E68) -> 2012.59 | G23: =E23/F23 -> 0.97351174 | H23: =E23/O23 -> 0.21634557 | I23: 2129.9248 | J23: -53.038595 | K23: 2294.5318 | L23: 2297.2978 | M23: 43.667283 | N23: 51.688897 | O23: 9056.252 | P23: 58.310592 | Q23: =AVERAGE(Data!L66:L68) -> 42.386969 | R23: =AVERAGE(Data!M66:M68) -> 87.569217 | S23: =Q23/R23 -> 0.4840396 | T23: 15482339 | U23: =AB23+AE23+AG23 -> 3275.0175 | V23: =AC23+AF23+AH23 -> 3257.4868 | W23: =U23/V23 -> 1.0053817 | X23: 2305.3176 | Y23: 2218.2729 | Z23: 261.55188 | AA23: 522.82351 | AB23: =X23+Z23 -> 2566.8695 | AC23: =Y23+AA23 -> 2741.0964 | AD23: =AB23/AC23 -> 0.93643897 | AE23: 39.897875 | AF23: 497.16086 | AG23: 668.25012 | AH23: 19.22956 | AI23: 7.029 | AJ23: 2.5 | AK23: 2012.5914 | AL23: 431.945 | AM23: 1494.0055 | AN23: 926.91939 | AQ23: =AG23-AH23 -> 649.02056
A24: 38504 | B24: 67.859768 | C24: 193.77654 | D24: =SUM(Data!C69:C71) -> 583.5 | E24: =SUM(Data!D69:D71) -> 1926.2 | F24: =SUM(Data!E69:E71) -> 2428.08 | G24: =E24/F24 -> 0.7933017 | H24: =E24/O24 -> 0.20206235 | I24: 2259.4192 | J24: 181.54509 | K24: 2394.7355 | L24: 2369.6788 | M24: -0.83945918 | N24: 52.030356 | O24: 9532.701 | P24: 58.85895 | Q24: =AVERAGE(Data!L69:L71) -> 42.915838 | R24: =AVERAGE(Data!M69:M71) -> 88.740253 | S24: =Q24/R24 -> 0.48361185 | T24: 15996968 | U24: =AB24+AE24+AG24 -> 3561.0108 | V24: =AC24+AF24+AH24 -> 3483.3491 | W24: =U24/V24 -> 1.0222951 | X24: 2562.3005 | Y24: 2390.5956 | Z24: 252.44723 | AA24: 527.72848 | AB24: =X24+Z24 -> 2814.7478 | AC24: =Y24+AA24 -> 2918.324 | AD24: =AB24/AC24 -> 0.9645083 | AE24: 46.263114 | AF24: 537.3423 | AG24: 699.99995 | AH24: 27.68273 | AI24: 8.476 | AJ24: 2.5 | AK24: 2428.0777 | AL24: 599.69354 | AM24: 1807.5348 | AN24: 1252.9403 | AQ24: =AG24-AH24 -> 672.31722
A25: 38596 | B25: 68.377844 | C25: 196.27552 | D25: =SUM(Data!C72:C74) -> 590.6 | E25: =SUM(Data!D72:D74) -> 2408.64 | F25: =SUM(Data!E72:E74) -> 2379.06 | G25: =E25/F25 -> 1.0124335 | H25: =E25/O25 -> 0.23337077 | I25: 2346.3052 | J25: -60.396773 | K25: 2618.7441 | L25: 2321.9019 | M25: 275.79059 | N25: 59.669853 | O25: 10321.087 | P25: 59.308309 | Q25: =AVERAGE(Data!L72:L74) -> 42.95478 | R25: =AVERAGE(Data!M72:M74) -> 89.820041 | S25: =Q25/R25 -> 0.47823158 | T25: 16340891 | U25: =AB25+AE25+AG25 -> 3795.1921 | V25: =AC25+AF25+AH25 -> 3405.7618 | W25: =U25/V25 -> 1.1143446 | X25: 2782.9461 | Y25: 2374.9804 | Z25: 254.67597 | AA25: 518.93459 | AB25: =X25+Z25 -> 3037.6221 | AC25: =Y25+AA25 -> 2893.915 | AD25: =AB25/AC25 -> 1.0496584 | AE25: 55.848027 | AF25: 470.56384 | AG25: 701.72195 | AH25: 41.282903 | AI25: 8.218 | AJ25: 2.5 | AK25: 2379.0575 | AL25: 640.202 | AM25: 1763.0157 | AN25: 1113.0331 | AQ25: =AG25-AH25 -> 660.43905
A26: 38687 | B26: 69.064973 | C26: 198.51557 | D26: =SUM(Data!C75:C77) -> 593.6 | E26: =SUM(Data!D75:D77) -> 2585.43 | F26: =SUM(Data!E75:E77) -> 2326.01 | G26: =E26/F26 -> 1.11153 | H26: =E26/O26 -> 0.2274143 | I26: 2442.2246 | J26: 273.97038 | K26: 2789.4784 | L26: 2593.8248 | M26: 197.57133 | N26: 62.022528 | O26: 11368.81 | P26: 59.904298 | Q26: =AVERAGE(Data!L75:L77) -> 43.38108 | R26: =AVERAGE(Data!M75:M77) -> 90.276289 | S26: =Q26/R26 -> 0.48053681 | T26: 18248352 | U26: =AB26+AE26+AG26 -> 3843.1009 | V26: =AC26+AF26+AH26 -> 3853.7982 | W26: =U26/V26 -> 0.99722422 | X26: 2817.1266 | Y26: 2725.5013 | Z26: 243.44627 | AA26: 572.4683 | AB26: =X26+Z26 -> 3060.5729 | AC26: =Y26+AA26 -> 3297.9696 | AD26: =AB26/AC26 -> 0.92801731 | AE26: 71.149946 | AF26: 523.61313 | AG26: 711.37805 | AH26: 32.215447 | AI26: 59.249 | AJ26: 2.5 | AK26: 2326.0169 | AL26: 539.75705 | AM26: 1805.9625 | AN26: 990.38824 | AQ26: =AG26-AH26 -> 679.1626
A27: 38777 | B27: 69.80051 | C27: 199.72929 | D27: =SUM(Data!C78:C80) -> 596.8 | E27: =SUM(Data!D78:D80) -> 2215.89 | F27: =SUM(Data!E78:E80) -> 2541.94 | G27: =E27/F27 -> 0.87173183 | H27: =E27/O27 -> 0.21083243 | I27: 2630.4753 | J27: 177.26274 | K27: 3154.6413 | L27: 2638.8477 | M27: 537.09925 | N27: 66.794543 | O27: 10510.195 | P27: 60.542274 | Q27: =AVERAGE(Data!L78:L80) -> 44.001276 | R27: =AVERAGE(Data!M78:M80) -> 90.762953 | S27: =Q27/R27 -> 0.48479335 | T27: 16174029 | U27: =AB27+AE27+AG27 -> 4150.9331 | V27: =AC27+AF27+AH27 -> 3666.8375 | W27: =U27/V27 -> 1.1320199 | X27: 3139.0276 | Y27: 2562.4727 | Z27: 250.86802 | AA27: 565.04754 | AB27: =X27+Z27 -> 3389.8956 | AC27: =Y27+AA27 -> 3127.5202 | AD27: =AB27/AC27 -> 1.0838925 | AE27: 67.803746 | AF27: 521.0035 | AG27: 693.23382 | AH27: 18.313748 | AI27: 4.727 | AJ27: 2.6 | AK27: 2541.9465 | AL27: 731.52087 | AM27: 1764.9923 | AN27: 1039.958 | AQ27: =AG27-AH27 -> 674.92007
A28: 38869 | B28: 69.984833 | C28: 201.47771 | D28: =SUM(Data!C81:C83) -> 606.9 | E28: =SUM(Data!D81:D83) -> 2343.49 | F28: =SUM(Data!E81:E83) -> 3098.64 | G28: =E28/F28 -> 0.75629631 | H28: =E28/O28 -> 0.21101512 | I28: 2887.4216 | J28: 364.31395 | K28: 3201.347 | L28: 2755.2851 | M28: 432.52728 | N28: 68.294545 | O28: 11105.792 | P28: 60.702149 | Q28: =AVERAGE(Data!L81:L83) -> 44.251173 | R28: =AVERAGE(Data!M81:M83) -> 92.298988 | S28: =Q28/R28 -> 0.47943292 | T28: 16669237 | U28: =AB28+AE28+AG28 -> 4522.2718 | V28: =AC28+AF28+AH28 -> 3922.5145 | W28: =U28/V28 -> 1.1529012 | X28: 3434.7551 | Y28: 2774.5544 | Z28: 257.15776 | AA28: 574.50399 | AB28: =X28+Z28 -> 3691.9129 | AC28: =Y28+AA28 -> 3349.0584 | AD28: =AB28/AC28 -> 1.1023734 | AE28: 71.77974 | AF28: 543.52232 | AG28: 758.5792 | AH28: 29.933773 | AI28: 6.084 | AJ28: 2.6 | AK28: 3098.6391 | AL28: 827.34996 | AM28: 2386.6073 | AN28: 1524.9427 | AQ28: =AG28-AH28 -> 728.64543
A29: 38961 | B29: 70.50975 | C29: 202.68732 | D29: =SUM(Data!C84:C86) -> 610.3 | E29: =SUM(Data!D84:D86) -> 2392.71 | F29: =SUM(Data!E84:E86) -> 2454.67 | G29: =E29/F29 -> 0.97475832 | H29: =E29/O29 -> 0.20545156 | I29: 2442.1426 | J29: 19.300756 | K29: 3164.3868 | L29: 3011.0361 | M29: 123.71207 | N29: 66.321646 | O29: 11646.103 | P29: 61.157442 | Q29: =AVERAGE(Data!L84:L86) -> 44.32381 | R29: =AVERAGE(Data!M84:M86) -> 92.81607 | S29: =Q29/R29 -> 0.47754457 | T29: 17236054 | U29: =AB29+AE29+AG29 -> 4546.4152 | V29: =AC29+AF29+AH29 -> 4213.8619 | W29: =U29/V29 -> 1.0789189 | X29: 3383.3222 | Y29: 3048.5813 | Z29: 268.76751 | AA29: 578.53947 | AB29: =X29+Z29 -> 3652.0898 | AC29: =Y29+AA29 -> 3627.1208 | AD29: =AB29/AC29 -> 1.006884 | AE29: 75.541664 | AF29: 535.58164 | AG29: 818.7838 | AH29: 51.159427 | AI29: 6.28 | AJ29: 2.6 | AK29: 2454.674 | AL29: 547.00908 | AM29: 2014.0746 | AN29: 1268.6961 | AQ29: =AG29-AH29 -> 767.62438
A30: 39052 | B30: 71.236893 | C30: 202.44265 | D30: =SUM(Data!C87:C89) -> 605.1 | E30: =SUM(Data!D87:D89) -> 2975.89 | F30: =SUM(Data!E87:E89) -> 3167.46 | G30: =E30/F30 -> 0.93951936 | H30: =E30/O30 -> 0.23943749 | I30: 3323.6636 | J30: 896.59606 | K30: 3202.6509 | L30: 2855.8046 | M30: 381.29365 | N30: 62.557473 | O30: 12428.672 | P30: 61.788138 | Q30: =AVERAGE(Data!L87:L89) -> 44.724334 | R30: =AVERAGE(Data!M87:M89) -> 92.02524 | S30: =Q30/R30 -> 0.48600074 | T30: 18857354 | U30: =AB30+AE30+AG30 -> 4513.3708 | V30: =AC30+AF30+AH30 -> 4189.8503 | W30: =U30/V30 -> 1.0772153 | X30: 3218.9868 | Y30: 3022.0771 | Z30: 259.73753 | AA30: 623.17919 | AB30: =X30+Z30 -> 3478.7243 | AC30: =Y30+AA30 -> 3645.2563 | AD30: =AB30/AC30 -> 0.95431541 | AE30: 71.442927 | AF30: 514.065 | AG30: 963.20356 | AH30: 30.528935 | AI30: 19.421 | AJ30: 2.6 | AK30: 3167.4591 | AL30: 1129.1267 | AM30: 2167.538 | AN30: 1119.1738 | AQ30: =AG30-AH30 -> 932.67462
A31: 39142 | B31: 71.240798 | C31: 204.6774 | D31: =SUM(Data!C90:C92) -> 611.267 | E31: =SUM(Data!D90:D92) -> 2272.38 | F31: =SUM(Data!E90:E92) -> 2728.76 | G31: =E31/F31 -> 0.83275187 | H31: =E31/O31 -> 0.20750959 | I31: 2822.2983 | J31: 200.37217 | K31: 3016.8122 | L31: 3038.3683 | M31: -15.453257 | N31: 62.652366 | O31: 10950.723 | P31: 61.791525 | Q31: =AVERAGE(Data!L90:L92) -> 44.906871 | R31: =AVERAGE(Data!M90:M92) -> 92.963134 | S31: =Q31/R31 -> 0.48306107 | T31: 16460616 | U31: =AB31+AE31+AG31 -> 4163.0114 | V31: =AC31+AF31+AH31 -> 4098.7001 | W31: =U31/V31 -> 1.0156907 | X31: 2999.8047 | Y31: 2902.183 | Z31: 273.33095 | AA31: 612.78766 | AB31: =X31+Z31 -> 3273.1356 | AC31: =Y31+AA31 -> 3514.9706 | AD31: =AB31/AC31 -> 0.93119856 | AE31: 79.343964 | AF31: 551.1426 | AG31: 810.5318 | AH31: 32.586853 | AI31: 60.8966 | AJ31: 2.5 | AK31: 2728.7546 | AL31: 572.96615 | AM31: 1919.7904 | AN31: 1156.7422 | AQ31: =AG31-AH31 -> 777.94495
A32: 39234 | B32: 71.176109 | C32: 206.77243 | D32: =SUM(Data!C93:C95) -> 622.987 | E32: =SUM(Data!D93:D95) -> 2615.5 | F32: =SUM(Data!E93:E95) -> 3300.95 | G32: =E32/F32 -> 0.79234766 | H32: =E32/O32 -> 0.22348239 | I32: 3045.5394 | J32: 236.1932 | K32: 3214.052 | L32: 2959.893 | M32: 227.34762 | N32: 61.630985 | O32: 11703.383 | P32: 61.735416 | Q32: =AVERAGE(Data!L93:L95) -> 45.008502 | R32: =AVERAGE(Data!M93:M95) -> 94.745543 | S32: =Q32/R32 -> 0.47504611 | T32: 16855707 | U32: =AB32+AE32+AG32 -> 4752.0242 | V32: =AC32+AF32+AH32 -> 4206.7555 | W32: =U32/V32 -> 1.1296174 | X32: 3480.896 | Y32: 2981.6206 | Z32: 301.92297 | AA32: 623.37685 | AB32: =X32+Z32 -> 3782.819 | AC32: =Y32+AA32 -> 3604.9975 | AD32: =AB32/AC32 -> 1.0493264 | AE32: 80.242146 | AF32: 562.51687 | AG32: 888.96306 | AH32: 39.241132 | AI32: 19.4922 | AJ32: 2.5 | AK32: 3300.9456 | AL32: 691.64011 | AM32: 2480.8021 | AN32: 1526.135 | AQ32: =AG32-AH32 -> 849.72192
A33: 39326 | B33: 72.268273 | C33: 207.36874 | D33: =SUM(Data!C96:C98) -> 624.706 | E33: =SUM(Data!D96:D98) -> 3360.95 | F33: =SUM(Data!E96:E98) -> 3814.82 | G33: =E33/F33 -> 0.88102453 | H33: =E33/O33 -> 0.26718281 | I33: 3826.5083 | J33: 404.34698 | K33: 3700.1941 | L33: 3249.2279 | M33: 439.42705 | N33: 71.197255 | O33: 12579.215 | P33: 62.682718 | Q33: =AVERAGE(Data!L96:L98) -> 45.4472 | R33: =AVERAGE(Data!M96:M98) -> 95.006973 | S33: =Q33/R33 -> 0.47835646 | T33: 17498795 | U33: =AB33+AE33+AG33 -> 5299.4952 | V33: =AC33+AF33+AH33 -> 4625.2364 | W33: =U33/V33 -> 1.1457782 | X33: 3970.0201 | Y33: 3329.7637 | Z33: 316.70418 | AA33: 654.82369 | AB33: =X33+Z33 -> 4286.7243 | AC33: =Y33+AA33 -> 3984.5874 | AD33: =AB33/AC33 -> 1.0758264 | AE33: 85.458678 | AF33: 598.81598 | AG33: 927.31226 | AH33: 41.833038 | AI33: 14.3488 | AJ33: 2.5 | AK33: 3814.8134 | AL33: 968.70973 | AM33: 2479.2729 | AN33: 1481.528 | AQ33: =AG33-AH33 -> 885.47922
A34: 39417 | B34: 73.262135 | C34: 210.54983 | D34: =SUM(Data!C99:C101) -> 629.149 | E34: =SUM(Data!D99:D101) -> 4056.63 | F34: =SUM(Data!E99:E101) -> 3786.08 | G34: =E34/F34 -> 1.0714591 | H34: =E34/O34 -> 0.27755851 | I34: 3913.7917 | J34: 626.9968 | K34: 4404.7421 | L34: 3621.7782 | M34: 796.37548 | N34: 93.695847 | O34: 14615.405 | P34: 63.544755 | Q34: =AVERAGE(Data!L99:L101) -> 45.973711 | R34: =AVERAGE(Data!M99:M101) -> 95.682676 | S34: =Q34/R34 -> 0.48048103 | T34: 19433027 | U34: =AB34+AE34+AG34 -> 5745.5463 | V34: =AC34+AF34+AH34 -> 5142.8963 | W34: =U34/V34 -> 1.1171811 | X34: 4419.4347 | Y34: 3833.5631 | Z34: 308.13183 | AA34: 680.57473 | AB34: =X34+Z34 -> 4727.5665 | AC34: =Y34+AA34 -> 4514.1378 | AD34: =AB34/AC34 -> 1.0472801 | AE34: 92.397631 | AF34: 593.0822 | AG34: 925.58217 | AH34: 35.676281 | AI34: 10.707337 | AJ34: 2.5 | AK34: 3786.079 | AL34: 1084.7439 | AM34: 2582.955 | AN34: 1400.8706 | AQ34: =AG34-AH34 -> 889.90589
A35: 39508 | B35: 74.99912 | C35: 213.05212 | D35: =SUM(Data!C102:C104) -> 636.301 | E35: =SUM(Data!D102:D104) -> 3663.68 | F35: =SUM(Data!E102:E104) -> 4921.2 | G35: =E35/F35 -> 0.74446883 | H35: =E35/O35 -> 0.26606182 | I35: 5084.1936 | J35: 871.96596 | K35: 4879.9117 | L35: 3854.4873 | M35: 868.09979 | N35: 102.81011 | O35: 13770.033 | P35: 65.051349 | Q35: =AVERAGE(Data!L102:L104) -> 47.279507 | R35: =AVERAGE(Data!M102:M104) -> 96.770372 | S35: =Q35/R35 -> 0.4885742 | T35: 17414431 | U35: =AB35+AE35+AG35 -> 6137.4308 | V35: =AC35+AF35+AH35 -> 4817.7035 | W35: =U35/V35 -> 1.2739329 | X35: 4803.6524 | Y35: 3665.4247 | Z35: 330.11935 | AA35: 668.3594 | AB35: =X35+Z35 -> 5133.7718 | AC35: =Y35+AA35 -> 4333.7841 | AD35: =AB35/AC35 -> 1.1845933 | AE35: 80.305507 | AF35: 457.32206 | AG35: 923.35354 | AH35: 26.597315 | AI35: 37.441 | AJ35: 2.6 | AK35: 4921.1936 | AL35: 2073.003 | AM35: 2645.8726 | AN35: 1492.1009 | AQ35: =AG35-AH35 -> 896.75622
A36: 39600 | B36: 77.630993 | C36: 215.84133 | D36: =SUM(Data!C105:C107) -> 650.27 | E36: =SUM(Data!D105:D107) -> 4980.08 | F36: =SUM(Data!E105:E107) -> 5883.99 | G36: =E36/F36 -> 0.84637805 | H36: =E36/O36 -> 0.32405128 | I36: 5495.7946 | J36: 413.17426 | K36: 5263.1428 | L36: 4328.3068 | M36: 1032.8703 | N36: 119.79716 | O36: 15368.185 | P36: 67.334134 | Q36: =AVERAGE(Data!L105:L107) -> 49.083114 | R36: =AVERAGE(Data!M105:M107) -> 98.894815 | S36: =Q36/R36 -> 0.49631635 | T36: 17990328 | U36: =AB36+AE36+AG36 -> 7118.6601 | V36: =AC36+AF36+AH36 -> 5570.4306 | W36: =U36/V36 -> 1.2779371 | X36: 5813.9316 | Y36: 4325.2773 | Z36: 365.59706 | AA36: 759.21482 | AB36: =X36+Z36 -> 6179.5287 | AC36: =Y36+AA36 -> 5084.4921 | AD36: =AB36/AC36 -> 1.2153679 | AE36: 81.711739 | AF36: 453.70069 | AG36: 857.4197 | AH36: 32.237812 | AI36: 27.52 | AJ36: 2.6 | AK36: 5883.9972 | AL36: 2747.9403 | AM36: 2961.2524 | AN36: 1829.1919 | AQ36: =AG36-AH36 -> 825.18189
A37: 39692 | B37: 79.445947 | C37: 218.38724 | D37: =SUM(Data!C108:C110) -> 657.833 | E37: =SUM(Data!D108:D110) -> 5996.31 | F37: =SUM(Data!E108:E110) -> 6255.67 | G37: =E37/F37 -> 0.95854001 | H37: =E37/O37 -> 0.3732452 | I37: 6391.7741 | J37: 154.63111 | K37: 5011.4009 | L37: 5013.7192 | M37: -4.228794 | N37: 114.37771 | O37: 16065.337 | P37: 68.908356 | Q37: =AVERAGE(Data!L108:L110) -> 49.970459 | R37: =AVERAGE(Data!M108:M110) -> 100.04502 | S37: =Q37/R37 -> 0.49947974 | T37: 18677591 | U37: =AB37+AE37+AG37 -> 6726.3621 | V37: =AC37+AF37+AH37 -> 6491.9494 | W37: =U37/V37 -> 1.0361082 | X37: 5420.3056 | Y37: 5210.428 | Z37: 377.99761 | AA37: 782.3657 | AB37: =X37+Z37 -> 5798.3032 | AC37: =Y37+AA37 -> 5992.7937 | AD37: =AB37/AC37 -> 0.96754594 | AE37: 90.933225 | AF37: 454.4236 | AG37: 837.1257 | AH37: 44.732056 | AI37: 19.7654 | AJ37: 2.6 | AK37: 6255.6628 | AL37: 2525.0566 | AM37: 3480.1765 | AN37: 1891.6506 | AQ37: =AG37-AH37 -> 792.39365
A38: 39783 | B38: 80.058203 | C38: 213.95845 | D38: =SUM(Data!C111:C113) -> 639.226 | E38: =SUM(Data!D111:D113) -> 7121 | F38: =SUM(Data!E111:E113) -> 5047.53 | G38: =E38/F38 -> 1.410789 | H38: =E38/O38 -> 0.44685321 | I38: 5216.0752 | J38: -913.66973 | K38: 3313.0654 | L38: 4413.0724 | M38: -1055.0617 | N38: 61.579263 | O38: 15935.882 | P38: 69.439402 | Q38: =AVERAGE(Data!L111:L113) -> 50.235625 | R38: =AVERAGE(Data!M111:M113) -> 97.215214 | S38: =Q38/R38 -> 0.51674653 | T38: 20777530 | U38: =AB38+AE38+AG38 -> 4636.1733 | V38: =AC38+AF38+AH38 -> 5969.1263 | W38: =U38/V38 -> 0.77669211 | X38: 3422.8778 | Y38: 4710.9728 | Z38: 367.90218 | AA38: 803.07954 | AB38: =X38+Z38 -> 3790.78 | AC38: =Y38+AA38 -> 5514.0523 | AD38: =AB38/AC38 -> 0.68747624 | AE38: 80.557688 | AF38: 396.88098 | AG38: 764.83567 | AH38: 58.193002 | AI38: 31.278148 | AJ38: 2.6 | AK38: 5047.5215 | AL38: 1329.2719 | AM38: 3453.1504 | AN38: 1706.2661 | AQ38: =AG38-AH38 -> 706.64266
A39: 39873 | B39: 80.892076 | C39: 212.89739 | D39: =SUM(Data!C114:C116) -> 636.045 | E39: =SUM(Data!D114:D116) -> 4259.51 | F39: =SUM(Data!E114:E116) -> 3446.17 | G39: =E39/F39 -> 1.2360127 | H39: =E39/O39 -> 0.31531104 | I39: 3611.0634 | J39: -1375.2474 | K39: 2779.4519 | L39: 3670.4289 | M39: -931.18604 | N39: 46.984913 | O39: 13508.915 | P39: 70.162672 | Q39: =AVERAGE(Data!L114:L116) -> 51.005053 | R39: =AVERAGE(Data!M114:M116) -> 96.731439 | S39: =Q39/R39 -> 0.52728517 | T39: 18181890 | U39: =AB39+AE39+AG39 -> 3879.6686 | V39: =AC39+AF39+AH39 -> 4533.7553 | W39: =U39/V39 -> 0.8557296 | X39: 2789.1636 | Y39: 3430.8795 | Z39: 320.24496 | AA39: 695.95676 | AB39: =X39+Z39 -> 3109.4085 | AC39: =Y39+AA39 -> 4126.8363 | AD39: =AB39/AC39 -> 0.75346059 | AE39: 65.872545 | AF39: 333.98522 | AG39: 704.38751 | AH39: 72.933737 | AI39: 30.529 | AJ39: 2.8 | AK39: 3446.165 | AL39: 652.35661 | AM39: 2567.3522 | AN39: 1629.4029 | AQ39: =AG39-AH39 -> 631.45377
A40: 39965 | B40: 81.899378 | C40: 213.37468 | D40: =SUM(Data!C117:C119) -> 642.789 | E40: =SUM(Data!D117:D119) -> 4682.94 | F40: =SUM(Data!E117:E119) -> 4781.94 | G40: =E40/F40 -> 0.97929711 | H40: =E40/O40 -> 0.32544142 | I40: 4397.1759 | J40: -424.65302 | K40: 3163.9533 | L40: 3252.3192 | M40: -93.580487 | N40: 55.366635 | O40: 14389.502 | P40: 71.036367 | Q40: =AVERAGE(Data!L117:L119) -> 51.774988 | R40: =AVERAGE(Data!M117:M119) -> 97.757084 | S40: =Q40/R40 -> 0.52962901 | T40: 18425949 | U40: =AB40+AE40+AG40 -> 4548.167 | V40: =AC40+AF40+AH40 -> 4397.9713 | W40: =U40/V40 -> 1.0341512 | X40: 3428.6511 | Y40: 3277.1209 | Z40: 326.05295 | AA40: 640.8013 | AB40: =X40+Z40 -> 3754.704 | AC40: =Y40+AA40 -> 3917.9222 | AD40: =AB40/AC40 -> 0.95834063 | AE40: 49.609691 | AF40: 412.42954 | AG40: 743.85331 | AH40: 67.619514 | AI40: 1939.46 | AJ40: 2.8 | AK40: 4781.9353 | AL40: 1215.7295 | AM40: 3301.2394 | AN40: 2136.3677 | AQ40: =AG40-AH40 -> 676.23379
...

Sheet Data trim_sa
A1: fecha | B1: v_1 | C1: v_2 | D1: v_3 | E1: v_4 | F1: v_5 | G1: v_6 | H1: v_7 | I1: v_8 | J1: v_9 | K1: v_10 | L1: v_11 | M1: v_12 | N1: v_13 | O1: v_14 | P1: v_15 | Q1: v_16 | R1: v_17 | S1: v_18 | T1: v_19 | U1: v_20 | V1: v_21 | W1: v_22 | X1: v_23 | Y1: v_24 | Z1: v_25 | AA1: v_26 | AB1: v_27 | AC1: v_28 | AD1: v_29 | AE1: v_30 | AF1: v_31 | AG1: v_32 | AH1: v_33 | AI1: v_34 | AJ1: v_35 | AK1: v_36 | AL1: v_37 | AM1: v_38 | AO1: gasto_2 | AP1: gasto_3 | AQ1: log1 | AR1: log2
A2: 37316 | B2: 58.202395 | C2: 178.16415 | D2: 1414.1844 | E2: 1548.5792 | F2: 49.457657 | G2: 1129.7825 | H2: 1408.6698 | I2: -248.95186 | J2: 21.502171 | K2: 6336.7849 | L2: 50.482517 | M2: 73.97726 | N2: 45.21796 | O2: 24.750528 | P2: 31.477672 | Q2: 75.211587 | R2: 24.224298 | S2: 28.967689 | T2: 69.689063 | V2: 26.536006 | W2: 73.63796 | X2: 1179.2513 | Y2: 1456.0294 | Z2: 215.34727 | AA2: 379.0215 | AB2: 1393.178 | AC2: 1813.8378 | AD2: 24.61169 | AE2: 302.42962 | AF2: 401.31316 | AG2: 14.023082 | AH2: 7.023 | AI2: 2 | AJ2: 1511.1507 | AK2: 390.52837 | AL2: 1160.9608 | AM2: 713.45522 | AO2: =D2/K2 -> 0.22317065 | AP2: =(1+D2/K2) -> 1.2231706 | AQ2: =LN(AO2) -> -1.4998186 | AR2: =LN(AP2) -> 0.20144638
A3: 37408 | B3: 59.724141 | C3: 179.32914 | D3: 1565.4094 | E3: 1601.0718 | F3: -19.173077 | G3: 1267.9003 | H3: 1653.0197 | I3: -370.96169 | J3: 26.497936 | K3: 6670.1135 | L3: 51.80242 | M3: 74.2356 | N3: 46.723576 | O3: 25.574643 | P3: 32.300679 | Q3: 75.703387 | R3: 25.030891 | S3: 29.725071 | T3: 70.144752 | V3: 26.802516 | W3: 74.18355 | X3: 1297.6771 | Y3: 1644.0435 | Z3: 216.9664 | AA3: 403.59948 | AB3: 1523.5768 | AC3: 2067.6361 | AD3: 23.096082 | AE3: 306.30429 | AF3: 416.38117 | AG3: 14.426365 | AH3: 11.68 | AI3: 2 | AJ3: 1623.2508 | AK3: 337.39943 | AL3: 1233.2325 | AM3: 711.71497 | AO3: =D3/K3 -> 0.23469008 | AP3: =(1+D3/K3) -> 1.2346901 | AQ3: =LN(AO3) -> -1.4494895 | AR3: =LN(AP3) -> 0.21081999
A4: 37500 | B4: 60.818873 | C4: 180.33218 | D4: 1513.0327 | E4: 1585.7014 | F4: 78.904321 | G4: 1295.0109 | H4: 1605.6532 | I4: -348.04417 | J4: 26.953621 | K4: 6961.5879 | L4: 52.751949 | M4: 74.59155 | N4: 48.377983 | O4: 26.480201 | P4: 32.892745 | Q4: 76.126815 | R4: 25.917195 | S4: 30.269926 | T4: 70.53709 | V4: 27.087363 | W4: 74.56645 | X4: 1356.3242 | Y4: 1601.6549 | Z4: 223.14556 | AA4: 415.96034 | AB4: 1578.6512 | AC4: 2009.645 | AD4: 19.198398 | AE4: 359.97354 | AF4: 432.04703 | AG4: 14.72421 | AH4: 7.9061 | AI4: 2 | AJ4: 1591.4063 | AK4: 345.79246 | AL4: 1194.6855 | AM4: 722.11408 | AO4: =D4/K4 -> 0.21734017 | AP4: =(1+D4/K4) -> 1.2173402 | AQ4: =LN(AO4) -> -1.5262916 | AR4: =LN(AP4) -> 0.19666829
A5: 37591 | B5: 61.804461 | C5: 181.65563 | D5: 1657.1315 | E5: 1656.6535 | F5: 94.427915 | G5: 1340.8122 | H5: 1504.7116 | I5: -150.36159 | J5: 29.342274 | K5: 7085.7114 | L5: 53.606809 | M5: 75.0244 | N5: 49.376779 | O5: 27.026902 | P5: 33.425781 | Q5: 76.685508 | R5: 26.452273 | S5: 30.760459 | T5: 71.05476 | V5: 27.229797 | W5: 74.91426 | X5: 1425.8254 | Y5: 1455.0367 | Z5: 228.54611 | AA5: 400.95839 | AB5: 1646.9559 | AC5: 1863.9348 | AD5: 16.271345 | AE5: 368.90923 | AF5: 457.10469 | AG5: 14.648272 | AH5: 8.0124 | AI5: 2 | AJ5: 1629.1947 | AK5: 423.03555 | AL5: 1185.4496 | AM5: 761.00683 | AO5: =D5/K5 -> 0.23386947 | AP5: =(1+D5/K5) -> 1.2338695 | AQ5: =LN(AO5) -> -1.4529922 | AR5: =LN(AP5) -> 0.21015514
A6: 37681 | B6: 63.828736 | C6: 183.32684 | D6: 1522.4655 | E6: 1660.0542 | F6: 129.03939 | G6: 1578.2739 | H6: 1558.141 | I6: 23.470858 | J6: 34.220287 | K6: 7561.4756 | L6: 55.362587 | M6: 75.3912 | N6: 51.79348 | O6: 28.349709 | P6: 34.520572 | Q6: 77.391007 | R6: 27.746955 | S6: 31.767953 | T6: 71.708457 | V6: 27.707482 | W6: 75.48714 | X6: 1631.4501 | Y6: 1614.1472 | Z6: 217.88613 | AA6: 412.94038 | AB6: 1847.2704 | AC6: 2006.5339 | AD6: 15.508245 | AE6: 379.03435 | AF6: 436.56627 | AG6: 0.73162719 | AH6: 38.481306 | AI6: 2.25 | AJ6: 1693.95 | AK6: 547.11031 | AL6: 1246.9423 | AM6: 788.47813 | AO6: =D6/K6 -> 0.20134502 | AP6: =(1+D6/K6) -> 1.201345 | AQ6: =LN(AO6) -> -1.6027353 | AR6: =LN(AP6) -> 0.18344178
A7: 37773 | B7: 64.633307 | C7: 183.12823 | D7: 1582.5311 | E7: 1629.4442 | F7: -22.178987 | G7: 1398.0534 | H7: 1518.0399 | I7: -124.02211 | J7: 29.11772 | K7: 7533.3393 | L7: 56.060442 | M7: 75.65644 | N7: 52.102928 | O7: 28.519089 | P7: 34.95571 | Q7: 77.307161 | R7: 27.912733 | S7: 32.168393 | T7: 71.630767 | V7: 28.702062 | W7: 75.56216 | X7: 1431.2782 | Y7: 1530.5191 | Z7: 216.92626 | AA7: 405.98938 | AB7: 1657.8018 | AC7: 1954.276 | AD7: 14.860808 | AE7: 400.46388 | AF7: 432.55878 | AG7: 1.227534 | AH7: 17.331481 | AI7: 2.25 | AJ7: 1651.7481 | AK7: 319.3399 | AL7: 1254.653 | AM7: 762.04478 | AO7: =D7/K7 -> 0.21007033 | AP7: =(1+D7/K7) -> 1.2100703 | AQ7: =LN(AO7) -> -1.5603129 | AR7: =LN(AP7) -> 0.19067848
A8: 37865 | B8: 65.371558 | C8: 184.23369 | D8: 1809.8389 | E8: 1823.3319 | F8: -15.561742 | G8: 1518.8011 | H8: 1563.724 | I8: -69.908429 | J8: 28.445305 | K8: 7821.0842 | L8: 56.700773 | M8: 76.08929 | N8: 53.342082 | O8: 29.197353 | P8: 35.354979 | Q8: 77.773829 | R8: 28.576576 | S8: 32.535825 | T8: 72.06317 | V8: 29.747351 | W8: 76.06002 | X8: 1574.0716 | Y8: 1610.9109 | Z8: 219.73084 | AA8: 409.19512 | AB8: 1792.6438 | AC8: 2009.5818 | AD8: 15.372044 | AE8: 380.67936 | AF8: 445.04945 | AG8: 18.865925 | AH8: 6.0976031 | AI8: 2.25 | AJ8: 1761.0996 | AK8: 421.08759 | AL8: 1307.4951 | AM8: 788.78491 | AO8: =D8/K8 -> 0.23140512 | AP8: =(1+D8/K8) -> 1.2314051 | AQ8: =LN(AO8) -> -1.4635853 | AR8: =LN(AP8) -> 0.20815589
A9: 37956 | B9: 65.786431 | C9: 185.11683 | D9: 1689.6627 | E9: 1772.9298 | F9: 250.49875 | G9: 1741.3533 | H9: 1603.9148 | I9: 180.88873 | J9: 32.500919 | K9: 8049.3086 | L9: 57.060617 | M9: 76.55272 | N9: 53.823933 | O9: 29.461099 | P9: 35.579355 | Q9: 78.146646 | R9: 28.834715 | S9: 32.74231 | T9: 72.408612 | V9: 30.45627 | W9: 76.43316 | X9: 1822.1877 | Y9: 1611.7988 | Z9: 226.88412 | AA9: 395.31807 | AB9: 2040.2929 | AC9: 2017.4775 | AD9: 16.769305 | AE9: 391.51653 | AF9: 475.56415 | AG9: 1.0263901 | AH9: 7.6914874 | AI9: 2.25 | AJ9: 1804.5495 | AK9: 312.22498 | AL9: 1343.9552 | AM9: 829.7208 | AO9: =D9/K9 -> 0.20991401 | AP9: =(1+D9/K9) -> 1.209914 | AQ9: =LN(AO9) -> -1.5610573 | AR9: =LN(AP9) -> 0.19054929
A10: 38047 | B10: 66.326534 | C10: 186.71285 | D10: 1787.5273 | E10: 1918.7608 | F10: 118.21221 | G10: 1739.4882 | H10: 1660.7248 | I10: 67.673952 | J10: 36.038825 | K10: 8396.4922 | L10: 57.529081 | M10: 77.09897 | N10: 55.006476 | O10: 30.108376 | P10: 35.87146 | Q10: 78.820404 | R10: 29.46823 | S10: 33.011122 | T10: 73.032897 | V10: 31.513628 | W10: 77.0226 | X10: 1783.1462 | Y10: 1688.9404 | Z10: 241.62166 | AA10: 465.17851 | AB10: 2023.4921 | AC10: 2139.5873 | AD10: 17.697735 | AE10: 435.57134 | AF10: 486.65567 | AG10: 1.1218982 | AH10: 5.3967888 | AI10: 2.5 | AJ10: 1950.5287 | AK10: 291.08009 | AL10: 1410.3901 | AM10: 862.9658 | AO10: =D10/K10 -> 0.21288977 | AP10: =(1+D10/K10) -> 1.2128898 | AQ10: =LN(AO10) -> -1.5469808 | AR10: =LN(AP10) -> 0.19300575
A11: 38139 | B11: 66.716009 | C11: 188.31622 | D11: 1925.2305 | E11: 1936.3442 | F11: -74.062393 | G11: 1932.1572 | H11: 1832.0244 | I11: 93.511676 | J11: 38.115748 | K11: 8671.4562 | L11: 57.866897 | M11: 77.72114 | N11: 55.754118 | O11: 30.517606 | P11: 36.0821 | Q11: 79.497261 | R11: 29.868759 | S11: 33.204967 | T11: 73.660056 | V11: 32.495652 | W11: 77.53995 | X11: 1964.8603 | Y11: 1819.0634 | Z11: 255.45685 | AA11: 481.24755 | AB11: 2231.006 | AC11: 2317.3202 | AD11: 22.391707 | AE11: 476.60544 | AF11: 498.31622 | AG11: 2.7709221 | AH11: 5.6165501 | AI11: 2.5 | AJ11: 1951.2135 | AK11: 492.01619 | AL11: 1381.0871 | AM11: 860.7288 | AO11: =D11/K11 -> 0.22201928 | AP11: =(1+D11/K11) -> 1.2220193 | AQ11: =LN(AO11) -> -1.504991 | AR11: =LN(AP11) -> 0.20050464
A12: 38231 | B12: 66.640867 | C12: 189.16226 | D12: 1870.2364 | E12: 2135.4849 | F12: 282.15273 | G12: 2002.3963 | H12: 1896.6952 | I12: 92.091342 | J12: 41.482443 | K12: 8973.9161 | L12: 57.801722 | M12: 78.21414 | N12: 56.778815 | O12: 31.078485 | P12: 36.041461 | Q12: 79.854415 | R12: 30.417713 | S12: 33.167568 | T12: 73.990985 | V12: 32.567124 | W12: 77.92186 | X12: 2063.5735 | Y12: 1953.242 | Z12: 257.6071 | AA12: 506.9841 | AB12: 2319.0541 | AC12: 2445.9801 | AD12: 26.824274 | AE12: 443.53895 | AF12: 509.14782 | AG12: 13.879282 | AH12: 6.0145196 | AI12: 2.5 | AJ12: 2089.4257 | AK12: 488.89313 | AL12: 1492.9999 | AM12: 900.56095 | AO12: =D12/K12 -> 0.20840806 | AP12: =(1+D12/K12) -> 1.2084081 | AQ12: =LN(AO12) -> -1.5682573 | AR12: =LN(AP12) -> 0.18930384
A13: 38322 | B13: 67.057985 | C13: 191.29958 | D13: 1875.7386 | E13: 2197.4753 | F13: 399.84056 | G13: 2071.6994 | H13: 2113.538 | I13: -14.101187 | J13: 49.827548 | K13: 9153.0831 | L13: 58.163514 | M13: 78.82054 | N13: 56.989001 | O13: 31.193532 | P13: 36.267051 | Q13: 80.756677 | R13: 30.530314 | S13: 33.37517 | T13: 74.826997 | V13: 33.142584 | W13: 78.5873 | X13: 2150.9195 | Y13: 2192.0791 | Z13: 259.33953 | AA13: 512.07888 | AB13: 2402.2826 | AC13: 2716.7852 | AD13: 32.454478 | AE13: 580.09802 | AF13: 552.95648 | AG13: 0.70515148 | AH13: 6.8226907 | AI13: 2.5 | AJ13: 2190.6819 | AK13: 651.373 | AL13: 1539.2459 | AM13: 978.503 | AO13: =D13/K13 -> 0.20492971 | AP13: =(1+D13/K13) -> 1.2049297 | AQ13: =LN(AO13) -> -1.5850883 | AR13: =LN(AP13) -> 0.18642123
... A41: 40878 | B41: 90.625336 | C41: 226.96056 | D41: 8110.1595 | E41: 8600.8229 | F41: 330.89367 | G41: 5842.7195 | H41: 6147.2152 | I41: -406.61436 | J41: 97.085138 | K41: 20641.679 | L41: 78.604927 | M41: 90.698 | N41: 94.645896 | O41: 51.805432 | P41: 49.01301 | Q41: 95.810882 | R41: 50.703976 | S41: 45.104785 | T41: 88.775824 | V41: 46.956041 | W41: 91.06976 | X41: 5988.1553 | Y41: 6164.7857 | Z41: 419.32662 | AA41: 783.69366 | AB41: 6411.556 | AC41: 6935.8545 | AD41: 25.343071 | AE41: 352.49587 | AF41: 698.31152 | AG41: 74.05274 | AH41: 20.668547 | AI41: 2.6 | AJ41: 8466.1925 | AK41: 3529.4884 | AL41: 4549.3472 | AM41: 2698.9453 | AO41: =D41/K41 -> 0.39290213 | AP41: =(1+D41/K41) -> 1.3929021 | AQ41: =LN(AO41) -> -0.93419474 | AR41: =LN(AP41) -> 0.33138943
